// El TRY CATCH sirve para que a pesar de un error nuestro c√≥digo siga corriendo

const numero1 = 30;
const numero3 = 90;

console.log(numero1);

try {
    console.log(numero2);    
} catch (error) {
    console.log(error);
}



console.log(numero3);